<?xml version="1.0"?>
<robot name="lidar_rover" xmlns:xacro="http://ros.org/wiki/xacro">

    <xacro:property name="base_width" value="0.16"/>
    <xacro:property name="base_length" value="0.22"/>
    <xacro:property name="base_height" value="0.05"/>

    <xacro:property name="wheel_radius" value="0.05"/>
    <xacro:property name="wheel_width" value="0.03"/>
    <xacro:property name="wheel_ygap" value="0.02"/>
    <xacro:property name="wheel_zoff" value="0.05"/>
    <xacro:property name="wheel_xoff" value="0.05"/>
    
    <xacro:property name="front_wheel_radius" value="0.0325"/>
    <xacro:property name="front_wheel_width" value="0.025"/>
    <xacro:property name="front_wheel_ygap" value="0.01"/>
    <xacro:property name="front_wheel_zoff" value="0.0675"/>

    <!-- Robot Base -->
    <link name="base_link">
        <visual>
            <geometry>
                <box size="${base_length} ${base_width} ${base_height}"/>
            </geometry>
            <material name="Red">
                <color rgba="1.0 0.0 0.0 1.0"/>
            </material>
        </visual>
        <collision>
            <geometry>
                <box size="${base_length} ${base_width} 0.01"/>
            </geometry>
        </collision>
    </link>
    
    <!-- Robot Footprint -->
    <link name="base_footprint" />

    <joint name="base_joint" type="fixed">
        <parent link="base_link"/>
        <child link="base_footprint"/>
        <origin xyz="0.0 0.0 ${-(wheel_radius+wheel_zoff)}" rpy="0 0 0"/>
    </joint>
    
    <!-- IMU Base -->
    <link name="imu_base" />

    <joint name="imu_joint" type="fixed">
        <parent link="base_link"/>
        <child link="imu_base"/>
        <origin xyz="0.0 ${base_length/2} 0.0" rpy="0 0 0"/>
    </joint>
    
    <!-- LIDAR Base -->
    <link name="scan_base">
        <visual>
            <geometry>
                <box size="${base_length/2} ${base_width} ${base_height/2}"/>
            </geometry>
            <material name="Red">
                <color rgba="1.0 0.0 0.0 1.0"/>
            </material>
        </visual>
        <collision>
            <geometry>
                <box size="${base_length/2} ${base_width} 0.01"/>
            </geometry>
        </collision>
    </link>

    <joint name="scan_joint" type="fixed">
        <parent link="base_link"/>
        <child link="scan_base"/>
        <origin xyz="${base_length/4} 0 ${(base_height/2)}" rpy="0 0 0"/>
    </joint>
    
    <!-- Wheels -->    
    <xacro:macro name="wheel" params="prefix x_reflect y_reflect">
        <link name="${prefix}_link">
            <visual>
                <origin xyz="0 0 0" rpy="${pi/2} 0 0"/>
                <geometry>
                    <cylinder radius="${wheel_radius}" length="${wheel_width}"/>
                </geometry>
                <material name="Black">
                    <color rgba="0.0 0.0 0.0 1.0"/>
                </material>
            </visual>
            <collision>
                <origin xyz="0 0 0" rpy="${pi/2} 0 0"/>
                <geometry>
                    <cylinder radius="${wheel_radius}" length="0.005"/>
                </geometry>
            </collision>
        </link>

        <joint name="${prefix}_joint" type="continuous">
            <parent link="base_link"/>
            <child link="${prefix}_link"/>
            <origin xyz="${x_reflect*wheel_xoff} ${y_reflect*(base_width/2+wheel_ygap)} ${-wheel_zoff}" rpy="0 0 0"/>
            <axis xyz="0 1 0"/>
        </joint>
    </xacro:macro>

    <xacro:wheel prefix="drive_wheel_l" x_reflect="-1" y_reflect="1" />
    <xacro:wheel prefix="drive_wheel_r" x_reflect="-1" y_reflect="-1" />
    
    <!-- Front wheels -->
    <xacro:macro name="front_wheel" params="prefix y_reflect">
        <link name="${prefix}_front_wheel_link">
            <visual>
                <origin xyz="0 0 0" rpy="${pi/2} 0 0"/>
                <geometry>
                    <cylinder radius="${front_wheel_radius}" length="${front_wheel_width}"/>
                </geometry>
                <material name="Black">
                    <color rgba="0.0 0.0 0.0 1.0"/>
                </material>
            </visual>
            <collision>
                <origin xyz="0 0 0" rpy="${pi/2} 0 0"/>
                <geometry>
                    <cylinder radius="${front_wheel_radius}" length="0.005"/>
                </geometry>
            </collision>
        </link>

        <joint name="${prefix}_front_wheel_joint" type="continuous">
            <parent link="base_link"/>
            <child link="${prefix}_front_wheel_link"/>
            <origin xyz="${base_width/2} ${y_reflect*(front_wheel_ygap)} ${-front_wheel_zoff}" rpy="0 0 0"/>
            <axis xyz="0 1 0"/>
        </joint>
    </xacro:macro>

    <xacro:front_wheel prefix="right" y_reflect="1" />
    <xacro:front_wheel prefix="left" y_reflect="-1" />
    

</robot>
