<?xml version="1.0"?>
<robot name="lidar_rover" xmlns:xacro="http://ros.org/wiki/xacro">

    <xacro:property name="base_width" value="0.16"/>
    <xacro:property name="base_length" value="0.22"/>
    <xacro:property name="base_height" value="0.07"/>

    <xacro:property name="wheel_radius" value="0.033"/>
    <xacro:property name="wheel_width" value="0.026"/>
    <xacro:property name="wheel_ygap" value="0.025"/>
    <xacro:property name="wheel_zoff" value="0.05"/>
    <xacro:property name="wheel_xoff" value="0.12"/>
    
    <xacro:macro name="box_inertia" params="m w h d">
        <inertial>
            <mass value="${m}"/>
            <inertia ixx="${m / 12.0 * (d*d + h*h)}" ixy="0.0" ixz="0.0" iyy="${m / 12.0 * (w*w + h*h)}" iyz="0.0" izz="${m / 12.0 * (w*w + d*d)}"/>
        </inertial>
    </xacro:macro>


    <!-- Robot Base -->
    <link name="base_link">
        <xacro:box_inertia m="10" w="${base_length}" h="${base_width}" d="0.01"/>
        <visual>
            <geometry>
                <box size="${base_length} ${base_width} ${base_height}"/>
            </geometry>
            <material name="Red">
                <color rgba="1.0 0.0 0.0 1.0"/>
            </material>
        </visual>
        <collision>
            <geometry>
                <box size="${base_length} ${base_width} 0.01"/>
            </geometry>
        </collision>
    </link>
    
    <!-- Robot Footprint -->
    <link name="base_footprint" />

    <joint name="base_joint" type="fixed">
        <parent link="base_link"/>
        <child link="base_footprint"/>
        <origin xyz="0.0 0.0 ${-(wheel_radius+wheel_zoff)}" rpy="0 0 0"/>
    </joint>
    
    <!-- IMU Base -->
    <link name="imu_base" />

    <joint name="imu_joint" type="fixed">
        <parent link="base_link"/>
        <child link="imu_base"/>
        <origin xyz="0.0 ${base_length/2} 0.0" rpy="0 0 0"/>
    </joint>
    
    <!-- LIDAR Base -->
    <link name="scan_base" />

    <joint name="scan_joint" type="fixed">
        <parent link="base_link"/>
        <child link="scan_base"/>
        <origin xyz="0.0 ${base_length/2} 0.04" rpy="0 0 0"/>
    </joint>
    
    <!-- Wheels -->
    <xacro:macro name="cylinder_inertia" params="m r h">
        <inertial>
            <mass value="${m}"/>
            <inertia ixx="${m*(3*r*r+h*h)/12}" ixy = "0" ixz = "0" iyy="${m*(3*r*r+h*h)/12}" iyz = "0" izz="${m*r*r/2}"/> 
        </inertial>
    </xacro:macro>
    
    <xacro:macro name="wheel" params="prefix x_reflect y_reflect">
        <link name="${prefix}_link">
            <visual>
                <origin xyz="0 0 0" rpy="${pi/2} 0 0"/>
                <geometry>
                    <cylinder radius="${wheel_radius}" length="${wheel_width}"/>
                </geometry>
                <material name="Black">
                    <color rgba="0.0 0.0 0.0 1.0"/>
                </material>
            </visual>
            <collision>
                <origin xyz="0 0 0" rpy="${pi/2} 0 0"/>
                <geometry>
                    <cylinder radius="${wheel_radius}" length="0.005"/>
                </geometry>
            </collision>
            <xacro:cylinder_inertia m="10" r="${wheel_radius}" h="0.005"/>
        </link>

        <joint name="${prefix}_joint" type="continuous">
            <parent link="base_link"/>
            <child link="${prefix}_link"/>
            <origin xyz="${x_reflect*wheel_xoff} ${y_reflect*(base_width/2+wheel_ygap)} ${-wheel_zoff}" rpy="0 0 0"/>
            <axis xyz="0 1 0"/>
        </joint>
    </xacro:macro>

    <xacro:wheel prefix="drive_wheel_l" x_reflect="-1" y_reflect="1" />
    <xacro:wheel prefix="drive_wheel_r" x_reflect="-1" y_reflect="-1" />
    <xacro:wheel prefix="front_wheel_l" x_reflect="1" y_reflect="1" />
    <xacro:wheel prefix="front_wheel_r" x_reflect="1" y_reflect="-1" />

</robot>
